Workbook

Sheet Calc
A1: Name | B1: Score | C1: Town | D1: Date | E1: Ok | G1: =SUM(B2:B11) -> 136.426
A2: Αλεξίου | B2: 12.5 | C2: Αθήνα | D2: 46096 | E2: =TRUE() -> TRUE | G2: =SUM(B:B) -> 136.426
A3: Βασιλείου | B3: 9 | C3: Πάτρα | D3: 46022 | E3: =FALSE() -> FALSE | G3: =AVERAGE(B2:B11) -> 17.05325
A4: Γεωργίου | C4: Αθήνα | D4: 46023 | E4: =TRUE() -> TRUE | G4: =COUNT(B2:B11) -> 8
A5: Δήμου | B5: 15.25 | C5: Λάρισα | D5: 45351 | E5: =TRUE() -> TRUE | G5: =COUNTA(A1:E11) -> 53
A6: Ελένη | B6: 7 | C6: Πάτρα | D6: 46311 | E6: =FALSE() -> FALSE | G6: =COUNTBLANK(B2:B11) -> 1
A7: Ζαχαρίου | B7: -3 | C7: αθήνα | D7: 36526 | E7: =TRUE() -> TRUE | G7: =MIN(B2:B11) -> -3
A8: Θεοδώρου | B8: 0 | C8: Βόλος | D8: 36525 | E8: =FALSE() -> FALSE | G8: =MAX(B2:B11) -> 100
A9: apple pie | B9: 100 | C9: Βόλος | D9: 46081 | E9: =TRUE() -> TRUE | G9: =MEDIAN(B2:B11) -> 5.8375
A10: Banana | B10: 2.675 | D10: 46203 | E10: =FALSE() -> FALSE | G10: =PRODUCT(B2,B3,B5) -> 1715.625
A11: cherry | B11: 0.001 | C11: Αθήνα | D11: 46204 | E11: =TRUE() -> TRUE | G11: =SUM(B2,3) -> 15.5
G12: =B2+B6 -> 19.5
G13: =B6*2 -> 14
G14: =B4+1 -> 1
G15: =A2&" "&C2 -> Αλεξίου Αθήνα
G16: =B2/B8 -> #DIV/0!
G17: =B2^2 -> 156.25
G18: =-B7^2 -> 9
G19: =10% -> 0.1
G20: =B2>B3 -> TRUE
G21: =A2="αλεξίου" -> TRUE
G22: =A2<A3 -> TRUE
G23: =1/3 -> 0.33333333
G24: =ROUND(B11*1000+0.5,0) -> 2
G25: =ROUND(2.675,2) -> 2.68
G26: =ROUND(-2.5,0) -> -3
G27: =ROUNDUP(1.21,1) -> 1.3
G28: =ROUNDDOWN(-1.29,1) -> -1.2
G29: =ROUND(1234.5678,-2) -> 1200
G30: =INT(-2.5) -> -3
G31: =TRUNC(-2.5) -> -2
G32: =MOD(10,3) -> 1
G33: =MOD(-10,3) -> 2
G34: =MOD(10,-3) -> -2
G35: =ABS(B7) -> 3
G36: =SQRT(16) -> 4
G37: =POWER(2,10) -> 1024
G38: =SIGN(B7) -> -1
G39: =CEILING(2.1,1) -> 3
G40: =FLOOR(2.9,1) -> 2
...

Sheet Data
A1: k | B1: v
A2: a | B2: 1
A3: b | B3: 2
A4: c | B4: 3
A5: d | B5: 4
